Workbook

Sheet Geral AT
B3: GERAL | G3: CIF | L3: FOB
B4: Ano | C4: Peças Expedidas | D4: Despesa Real | E4: Custo Peça Expedida | G4: Ano | H4: Peças Expedidas | I4: Despesa Real | J4: Custo Peça Expedida | L4: Ano | M4: Peças Expedidas | N4: Despesa Real | O4: Custo Peça Expedida
B5: 2022 | C5: 3788321 | D5: 10769256 | E5: =D5/C5 -> 2.8427517 | G5: 2022 | H5: 2340461 | I5: 10769256 | J5: =I5/H5 -> 4.6013397 | L5: 2022 | M5: 1447860 | N5: 10769256
B6: 2023 | C6: 2908636 | D6: 14181854 | E6: =D6/C6 -> 4.8757748 | G6: 2023 | H6: 1683240 | I6: 14181854 | J6: =I6/H6 -> 8.4253309 | L6: 2023 | M6: 1225396 | N6: 14181854
B7: 2024 | C7: 3289442 | D7: 13082060 | E7: =D7/C7 -> 3.9769845 | G7: 2024 | H7: 2030066 | I7: 13082060 | J7: =I7/H7 -> 6.444155 | L7: 2024 | M7: 1259376 | N7: 13082060
B8: 2025 | C8: 2364001 | D8: 10357371 | E8: =D8/C8 -> 4.3812888 | G8: 2025 | H8: 1627152 | I8: 10357371 | J8: =I8/H8 -> 6.3653371 | L8: 2025 | M8: 736849 | N8: 10357371
B9: Total Geral | C9: =SUM(C5:C8) -> 12350400 | G9: Total Geral | H9: =SUM(H5:H8) -> 7680919 | L9: Total Geral | M9: =SUM(M5:M8) -> 4669481

Sheet Detalhamento Embalagem
A1: Ano | B1: Jan | C1: Fev | D1: Mar | E1: Abr | F1: Mai | G1: Jun | H1: Jul | I1: Ago | J1: Set | K1: Out | L1: Nov | M1: Dez | N1: Total Gasto | O1: Total Expedido | P1: Peças Expedidas | Q1: Produto Acabado | R1: Display | S1: Custo Embalagem Peça
A2: 2022 | B2: 88708.48 | C2: 89132.84 | D2: 115882.61 | E2: 206750.53 | F2: 128667.54 | G2: 156783.47 | H2: 97035.2 | I2: 141822.77 | J2: 176881.21 | K2: 64948.89 | L2: 141063.36 | M2: 103661.54 | N2: =SUM(B2:M2) -> 1511338.4 | O2: =SUM(P2:R2) -> 2340461 | P2: 2306170 | Q2: 19741 | R2: 14550 | S2: =N2/O2 -> 0.64574391
A3: 2023 | B3: 206698.89 | C3: 113371.61 | D3: 118907.06 | E3: 91323.25 | F3: 62787.03 | G3: 199447.7 | H3: 185207.89 | I3: 128038.96 | J3: 106603.53 | K3: 130366.85 | L3: 164116.54 | M3: 163800.57 | N3: =SUM(B3:M3) -> 1670669.9 | O3: =SUM(P3:R3) -> 1683240 | P3: 1642194 | Q3: 18516 | R3: 22530 | S3: =N3/O3 -> 0.99253219
A4: 2024 | B4: 146132.84 | C4: 197495.89 | D4: 146266.14 | E4: 87593.21 | F4: 241947.77 | G4: 77384.34 | H4: 134034.1 | I4: 219286.02 | J4: 98368.21 | K4: 189383.39 | L4: 154909.55 | M4: 141661.26 | N4: =SUM(B4:M4) -> 1834462.7 | O4: =SUM(P4:R4) -> 2030066 | P4: 1999338 | Q4: 21646 | R4: 9082 | S4: =N4/O4 -> 0.90364684
A5: 2025 | B5: 66666.8 | C5: 204065.51 | D5: 220407.73 | E5: 148897.08 | F5: 102752.57 | G5: 160987.71 | H5: 173852.4 | I5: 167658.79 | J5: 89648.04 | N5: =SUM(B5:M5) -> 1334936.6 | O5: =SUM(P5:R5) -> 1627152 | P5: 1593398 | Q5: 23051 | R5: 10703 | S5: =N5/O5 -> 0.82041299

Sheet Análise Correios 2026
A2: Analise dos Correios anos Anteriores
A3: Ano | B3: Jan | C3: Fev | D3: Mar | E3: Abr | F3: Mai | G3: Jun | H3: Jul | I3: Ago | J3: Set | K3: Out | L3: Nov | M3: Dez | N3: Total Frete Correios R$ | O3: Total Expedido QTD | P3: Custo Frete Peça | Q3: Peças Expedidas QTD | R3: Produto Acabado
A4: 2022 | B4: 88265.02 | C4: 81505.28 | D4: 52202.65 | E4: 48986.67 | F4: 57440.04 | G4: 1482.65 | H4: 58119.08 | I4: 51753.73 | J4: 50036.41 | K4: 48824.29 | L4: 42139.46 | M4: 101595.94 | N4: =SUM(B4:M4) -> 682351.22 | O4: =SUM(Q4:R4) -> 85664 | P4: =N4/O4 -> 7.9654373 | Q4: 85661 | R4: 3
A5: 2023 | B5: 1198.96 | C5: 45930.6 | D5: 62570.96 | E5: 767.26 | F5: 99418.36 | G5: 89162.4 | H5: 121377.36 | I5: 104655.61 | J5: 978.53 | K5: 4941.93 | L5: 139314.46 | M5: 143138.47 | N5: =SUM(B5:M5) -> 813454.9 | O5: =SUM(Q5:R5) -> 140079 | P5: =N5/O5 -> 5.8071153 | Q5: 140077 | R5: 2
A6: 2024 | B6: 138661.36 | C6: 148156.97 | D6: 134999 | E6: 80458.36 | F6: 6386.39 | G6: 4225.1 | H6: 2933.1 | I6: 3902.41 | J6: 3944.45 | K6: 97389.6 | L6: 117410.09 | M6: 3358.37 | N6: =SUM(B6:M6) -> 741825.2 | O6: =SUM(Q6:R6) -> 56175 | P6: =N6/O6 -> 13.205611 | Q6: 56168 | R6: 7
A9: Cenário 2025 - Base Faturas Pagas
A11: Ano | B11: Peças
B12: Jan | C12: Fev | D12: Mar | E12: Abr | F12: Mai | G12: Jun | H12: Jul | I12: Ago | J12: Set | K12: Total | L12: Média
A13: 2025 | H13: 14802 | I13: 16908 | J13: 11471 | K13: =SUM(B13:J13) -> 43181 | L13: =AVERAGE(B13:J13) -> 14393.667
A14: Frete Pago | H14: 172295.28 | I14: 229711.92 | J14: 153904.92 | K14: =SUM(B14:J14) -> 555912.11 | L14: =AVERAGE(B14:J14) -> 185304.04
A15: Valor Pago Unidade | H15: 11.64 | I15: 13.59 | J15: 13.42 | L15: =AVERAGE(B15:J15) -> 12.883333
A17: Cenário Proposto 2026
A18: Ano | B18: Peças
B19: Jan | C19: Fev | D19: Mar | E19: Abr | F19: Mai | G19: Jun | H19: Jul | I19: Ago | J19: Set | K19: Out | L19: Nov | M19: Dez
A20: Expedição Correios | B20: ='Análise Frete Transp 2026'!B36 -> 9813.844 | C20: ='Análise Frete Transp 2026'!C36 -> 7041.752 | D20: ='Análise Frete Transp 2026'!D36 -> 7134.504 | E20: ='Análise Frete Transp 2026'!E36 -> 7223.168 | F20: ='Análise Frete Transp 2026'!F36 -> 6783.808 | G20: ='Análise Frete Transp 2026'!G36 -> 8441.892 | H20: ='Análise Frete Transp 2026'!H36 -> 9101.9652 | I20: ='Análise Frete Transp 2026'!I36 -> 8280.2184 | ... M20: ='Análise Frete Transp 2026'!M36 -> 7264.0016
A21: Média Peça | B21: 12.88 | C21: 12.88 | D21: 12.88 | E21: 12.88 | F21: 12.88 | G21: 12.88 | H21: 12.88 | I21: 12.88 | J21: 12.88 | K21: 12.88 | L21: 12.88 | M21: 12.88
A22: Frete Orçado | B22: =B20*B21 -> 126402.31 | C22: =C20*C21 -> 90697.766 | D22: =D20*D21 -> 91892.412 | E22: =E20*E21 -> 93034.404 | F22: =F20*F21 -> 87375.447 | G22: =G20*G21 -> 108731.57 | H22: =H20*H21 -> 117233.31 | I22: =I20*I21 -> 106649.21 | ... M22: =M20*M21 -> 93560.341
A24: Comparativo (Anos) Correios | E24: OBS
A25: Ano | B25: Orçado | C25: Realizado | D25: Saldo
A26: 2026 | B26: =SUM(B22:M22) -> 1278387.3
A27: 2025 | B27: 989714.18 | C27: 559528.5 | D27: =B27-C27 -> 430185.68
A28: 2024 | B28: 537466.65 | C28: 741825.2 | D28: =B28-C28 -> -204358.55
A29: 2023 | B29: 845637.02 | C29: 813454.9 | D29: =B29-C29 -> 32182.12

Sheet Detalhamento Frete
A1: Ano | B1: Jan | C1: Fev | D1: Mar | E1: Abr | F1: Mai | G1: Jun | H1: Jul | I1: Ago | J1: Set | K1: Out | L1: Nov | M1: Dez | N1: Total Frete | O1: Total Expedido CIF | P1: Peças Expedidas | Q1: Produto Acabado | S1: Display | T1: Custo Frete Peça
A2: 2022 | B2: ='Análise Frete Transp 2026'!B2+'Análise Correios 2026'!B4 -> 930813.47 | C2: ='Análise Frete Transp 2026'!C2+'Análise Correios 2026'!C4 -> 674807.28 | D2: ='Análise Frete Transp 2026'!D2+'Análise Correios 2026'!D4 -> 894883.44 | E2: ='Análise Frete Transp 2026'!E2+'Análise Correios 2026'!E4 -> 665255.89 | F2: ='Análise Frete Transp 2026'!F2+'Análise Correios 2026'!F4 -> 819103.64 | G2: ='Análise Frete Transp 2026'!G2+'Análise Correios 2026'!G4 -> 803327.71 | H2: ='Análise Frete Transp 2026'!H2+'Análise Correios 2026'!H4 -> 697967.72 | I2: ='Análise Frete Transp 2026'!I2+'Análise Correios 2026'!I4 -> 1212842.4 | ... M2: ='Análise Frete Transp 2026'!M2+'Análise Correios 2026'!M4 -> 678219.75 | N2: =SUM(B2:M2) -> 9729191.7 | O2: =SUM(P2:S2) -> 2340461 | P2: 2306170 | Q2: 19741 | S2: 14550 | T2: =N2/O2 -> 4.1569553
A3: 2023 | B3: ='Análise Frete Transp 2026'!B3+'Análise Correios 2026'!B5 -> 987558.71 | C3: ='Análise Frete Transp 2026'!C3+'Análise Correios 2026'!C5 -> 916096.9 | D3: ='Análise Frete Transp 2026'!D3+'Análise Correios 2026'!D5 -> 1070225.7 | E3: ='Análise Frete Transp 2026'!E3+'Análise Correios 2026'!E5 -> 903914.5 | F3: ='Análise Frete Transp 2026'!F3+'Análise Correios 2026'!F5 -> 1181976.2 | G3: ='Análise Frete Transp 2026'!G3+'Análise Correios 2026'!G5 -> 1264348.9 | H3: ='Análise Frete Transp 2026'!H3+'Análise Correios 2026'!H5 -> 1228270.8 | I3: ='Análise Frete Transp 2026'!I3+'Análise Correios 2026'!I5 -> 1123744.2 | ... M3: ='Análise Frete Transp 2026'!M3+'Análise Correios 2026'!M5 -> 1190593.3 | N3: =SUM(B3:M3) -> 12351394 | O3: =SUM(P3:S3) -> 1683240 | P3: 1642194 | Q3: 18516 | S3: 22530 | T3: =N3/O3 -> 7.3378686
A4: 2024 | B4: ='Análise Frete Transp 2026'!B4+'Análise Correios 2026'!B6 -> 474383.84 | C4: ='Análise Frete Transp 2026'!C4+'Análise Correios 2026'!C6 -> 1098917.2 | D4: ='Análise Frete Transp 2026'!D4+'Análise Correios 2026'!D6 -> 764247.93 | E4: ='Análise Frete Transp 2026'!E4+'Análise Correios 2026'!E6 -> 1303732 | F4: ='Análise Frete Transp 2026'!F4+'Análise Correios 2026'!F6 -> 902712.51 | G4: ='Análise Frete Transp 2026'!G4+'Análise Correios 2026'!G6 -> 629009.85 | H4: ='Análise Frete Transp 2026'!H4+'Análise Correios 2026'!H6 -> 680416.01 | I4: ='Análise Frete Transp 2026'!I4+'Análise Correios 2026'!I6 -> 990550.54 | ... M4: ='Análise Frete Transp 2026'!M4+'Análise Correios 2026'!M6 -> 1305365.2 | N4: =SUM(B4:M4) -> 11114038 | O4: =SUM(P4:S4) -> 2030066.2 | P4: 1999338 | Q4: 21646 | R4: =(Q4-Q3)/Q3 -> 0.16904299 | S4: 9082 | T4: =N4/O4 -> 5.4747172
A5: 2025 | B5: ='Análise Frete Transp 2026'!#REF!+'Análise Correios 2026'!#REF! -> #REF! | C5: ='Análise Frete Transp 2026'!#REF!+'Análise Correios 2026'!#REF! -> #REF! | D5: ='Análise Frete Transp 2026'!#REF!+'Análise Correios 2026'!#REF! -> #REF! | E5: ='Análise Frete Transp 2026'!#REF!+'Análise Correios 2026'!#REF! -> #REF! | F5: ='Análise Frete Transp 2026'!#REF!+'Análise Correios 2026'!#REF! -> #REF! | G5: ='Análise Frete Transp 2026'!#REF!+'Análise Correios 2026'!#REF! -> #REF! | H5: ='Análise Frete Transp 2026'!#REF!+'Análise Correios 2026'!#REF! -> #REF! | I5: ='Análise Frete Transp 2026'!#REF!+'Análise Correios 2026'!#REF! -> #REF! | J5: ='Análise Frete Transp 2026'!#REF!+'Análise Correios 2026'!#REF! -> #REF! | N5: =SUM(B5:M5) -> #REF! | O5: =SUM(P5:S5) -> 1627152.1 | P5: 1593398 | Q5: 23051 | R5: =(Q5-Q4)/Q4 -> 0.064908066 | S5: 10703 | T5: =N5/O5 -> #REF!
O7: 180000
O8: =O7*T5 -> #REF!
O9: =O8*12 -> #REF!
Q11: =Q5/9 -> 2561.2222
Q12: =Q11*1.17 -> 2996.63

Sheet Análise Frete Transp 2026
A1: Ano | B1: Jan | C1: Fev | D1: Mar | E1: Abr | F1: Mai | G1: Jun | H1: Jul | I1: Ago | J1: Set | K1: Out | L1: Nov | M1: Dez | N1: Total Frete | O1: Total Expedido | P1: Pçs Expedidas | Q1: Produtos Expedidos | R1: Display | S1: Custo Frete Peça
A2: 2022 | B2: 842548.45 | C2: 593302 | D2: 842680.79 | E2: 616269.22 | F2: 761663.6 | G2: 801845.06 | H2: 639848.64 | I2: 1161088.7 | J2: 275260.17 | K2: 1220286.5 | L2: 715423.56 | M2: 576623.81 | N2: =SUM(B2:M2) -> 9046840.5 | O2: =SUM(P2:R2) -> 2254026 | P2: 2220509 | Q2: 19738 | R2: 13779 | S2: =N2/O2 -> 4.0136363
A3: 2023 | B3: 986359.75 | C3: 870166.3 | D3: 1007654.7 | E3: 903147.24 | F3: 1082557.9 | G3: 1175186.5 | H3: 1106893.4 | I3: 1019088.6 | J3: 662911.77 | K3: 873950.5 | L3: 802567.42 | M3: 1047454.9 | N3: =SUM(B3:M3) -> 11537939 | O3: =SUM(P3:R3) -> 1542177 | P3: 1502117 | Q3: 18514 | R3: 21546 | S3: =N3/O3 -> 7.4815919
A4: 2024 | B4: 335722.48 | C4: 950760.21 | D4: 629248.93 | E4: 1223273.6 | F4: 896326.12 | G4: 624784.75 | H4: 677482.91 | I4: 986648.13 | J4: 612564.51 | K4: 1253044.1 | L4: 880350.24 | M4: 1302006.9 | N4: =SUM(B4:M4) -> 10372213 | O4: =SUM(P4:R4) -> 1973720 | P4: 1943170 | Q4: 21639 | R4: 8911 | S4: =N4/O4 -> 5.2551592
A5: 2025 | B5: 1001898.1 | C5: 809656.21 | D5: 819691.68 | E5: 716399.91 | F5: 654641.95 | G5: 1447312.3 | H5: 432813.6 | I5: 1619438.4 | J5: 666605.23 | K5: 858771.31 | N5: =SUM(B5:K5) -> 9027228.6 | O5: =SUM(P5:R5) -> 1853654 | P5: =P18 -> 1808467 | Q5: =P24 -> 28468 | R5: =P12 -> 16719 | S5: =N5/O5 -> 4.8699642
A6: 2026
A8: Cenário 2025 - Base Despesa Realizada
B10: Display
B11: Jan | C11: Fev | D11: Mar | E11: Abr | F11: Mai | G11: Jun | H11: Jul | I11: Ago | J11: Set | K11: Out | L11: Nov | M11: Dez | N11: Total | O11: Média | Q11: Indexador % | R11: Premissas Orçamentárias
A12: 2025 | B12: 1513 | C12: 1279 | D12: 936 | E12: 1083 | F12: 1147 | G12: 1384 | H12: 2457 | I12: 1499 | J12: 2458 | K12: 2963 | L12: =J12*(1+Q12) -> 2752.96 | M12: =J12*(1+Q12) -> 2752.96 | N12: =SUM(B12:M12) -> 22224.92 | O12: =AVERAGE(B12:M12) -> 1852.0767 | P12: =SUM(B12:K12) -> 16719 | Q12: 0.12 | R12: Display - Acréscimo de 12 % nos últimos 3 meses, devido epidemia de TV.
A13: Frete Pago | B13: =B12*B14 -> 73386.132 | C13: =C12*C14 -> 53465.338 | D13: =D12*D14 -> 41250.903 | E13: =E12*E14 -> 50809.489 | F13: =F12*F14 -> 59934.067 | G13: =G12*G14 -> 95196.163 | H13: =H12*H14 -> 106946.43 | I13: =I12*I14 -> 68708.929 | ... K13: =K12*K14 -> 132386.84 | L13: =L12*O14 -> 131668.6 | M13: =M12*O14 -> 131668.6 | N13: =SUM(B13:M13) -> 1047021.9 | O13: =AVERAGE(B13:M13) -> 87251.829
A14: Valor Pago Dislp. | B14: 48.503723 | C14: 41.802454 | D14: 44.071478 | E14: 46.915502 | F14: 52.252892 | G14: 68.783355 | H14: 43.527242 | I14: 45.83651 | J14: 41.3346 | K14: 44.68 | L14: 48.114195 | M14: 48.114195 | O14: =AVERAGE(B14:M14) -> 47.828012
B16: Peças
B17: Jan | C17: Fev | D17: Mar | E17: Abr | F17: Mai | G17: Jun | H17: Jul | I17: Ago | J17: Set | K17: Out | L17: Nov | M17: Dez | N17: Total | O17: Média | Q17: Indexador % | R17: Premissas Orçamentárias
A18: 2025 | B18: 175659 | C18: 200806 | D18: 181310 | E18: 198138 | F18: 173320 | G18: 146913 | H18: 199207 | I18: 173629 | J18: 187476 | K18: 172009 | L18: =AVERAGE(B18:K18) -> 180846.7 | M18: =AVERAGE(B18:L18) -> 180846.7 | N18: =SUM(B18:M18) -> 2170160.4 | O18: =AVERAGE(B18:J18) -> 181828.67 | P18: =SUM(B18:K18) -> 1808467 | R18: Out/Nov/Dez, projeção com base na média do ano.
A19: Frete Pago | B19: =B18*B20 -> 784669.98 | C19: =C18*C20 -> 511610.29 | D19: =D18*D20 -> 637973.68 | E19: =E18*E20 -> 769225.71 | F19: =F18*F20 -> 720470.66 | G19: =G18*G20 -> 548514.72 | H19: =H18*H20 -> 527523.27 | I19: =I18*I20 -> 520291.18 | J19: =J18*J20 -> 365788.03 | K19: =K20*K18 -> 631273.03 | L19: =P20*L18 -> 600411.04 | M19: =P20*M18 -> 600411.04 | N19: =SUM(B19:M19) -> 7218162.6 | O19: =AVERAGE(B19:M19) -> 601513.55
A20: Valor Pago Pç | B20: 4.467007 | C20: 2.5477839 | D20: 3.51869 | E20: 3.8822725 | F20: 4.1568813 | G20: 3.7336023 | H20: 2.6481161 | I20: 2.9965684 | J20: 1.9511192 | K20: 3.67 | L20: =L19/L18 -> 3.32 | M20: =M19/M18 -> 3.32 | O20: =AVERAGE(B20:M20) -> 3.3510034 | P20: 3.32
B22: Produto Acabado
B23: Jan | C23: Fev | D23: Mar | E23: Abr | F23: Mai | G23: Jun | H23: Jul | I23: Ago | J23: Set | K23: Out | L23: Nov | M23: Dez | N23: Total | O23: Média | Q23: Indexador % | R23: Premissas Orçamentárias
A24: 2025 | B24: 2996 | C24: 2276 | D24: 1887 | E24: 2149 | F24: 1877 | G24: 2220 | H24: 2310 | I24: 4613 | J24: 4376 | K24: 3764 | L24: =AVERAGE(B24:K24) -> 2846.8 | M24: =AVERAGE(B24:L24) -> 2846.8 | N24: =SUM(B24:M24) -> 34161.6 | O24: =AVERAGE(B24:M24) -> 2846.8 | P24: =SUM(B24:K24) -> 28468 | R24: Out/Nov/Dez, projeção com base na média do ano.
A25: Frete Pago | B25: =B24*B26 -> 136025.8 | C25: =C24*C26 -> 100973.5 | D25: =D24*D26 -> 76710.079 | E25: =E24*E26 -> 102396.56 | F25: =F24*F26 -> 100473.45 | G25: =G24*G26 -> 112231.51 | H25: =H24*H26 -> 115494.74 | I25: =I24*I26 -> 195573.68 | J25: =J24*J26 -> 183756.72 | K25: =K24*P26 -> 174204.86 | L25: =L24*P26 -> 131755.15 | M25: =M24*P26 -> 131755.15 | N25: =SUM(B25:M25) -> 1561351.2 | O25: =AVERAGE(B25:M25) -> 130112.6
A26: Valor Pago Acb. | B26: 45.402469 | C26: 44.364454 | D26: 40.65187 | E26: 47.648468 | F26: 53.528743 | G26: 50.554732 | H26: 49.997722 | I26: 42.396202 | J26: 41.991939 | K26: =K25/K24 -> 46.281844 | L26: =L25/L24 -> 46.281844 | M26: =M25/M24 -> 46.281844 | O26: =AVERAGE(B26:M26) -> 46.281844 | P26: 46.281844
B29: Cenário Proposto 2026
A31: Ano | B31: Peças
B32: Jan | C32: Fev | D32: Mar | E32: Abr | F32: Mai | G32: Jun | H32: Jul | I32: Ago | J32: Set | K32: Out | L32: Nov | M32: Dez | O32: % Indexador | P32: Premissas Orçamentárias
A33: Vol, 2026 PCM | B33: 355513 | C33: 256084 | D33: 259468 | E33: 262386 | F33: 246586 | G33: 305569 | H33: 329025.9 | I33: 299497.8 | J33: 343180.84 | K33: 356398.76 | L33: 316897.6 | M33: 262587.2
A34: Vol FOB | B34: =B33*($O$34) -> 106653.9 | C34: =C33*($O$34) -> 76825.2 | D34: =D33*($O$34) -> 77840.4 | E34: =E33*($O$34) -> 78715.8 | F34: =F33*($O$34) -> 73975.8 | G34: =G33*($O$34) -> 91670.7 | H34: =H33*($O$34) -> 98707.77 | I34: =I33*($O$34) -> 89849.34 | ... M34: =M33*($O$34) -> 78776.16 | O34: 0.3 | P34: FOB - Considerado 30% do volume para 2026
A35: Vol. Display | B35: 3513 | C35: 3215 | D35: 3265 | E35: 3091 | F35: 3015 | G35: 2851 | H35: 2769 | I35: 2643 | J35: 2551 | K35: 2459 | L35: 2311 | M35: 2211 | O35: 0.01 | P35: Display - Considerado 1% do volume para 2026
A36: Expedição Correios | B36: =(B33-(B34+B35))*($O$36) -> 9813.844 | C36: =(C33-(C34+C35))*($O$36) -> 7041.752 | D36: =(D33-(D34+D35))*($O$36) -> 7134.504 | E36: =(E33-(E34+E35))*($O$36) -> 7223.168 | F36: =(F33-(F34+F35))*($O$36) -> 6783.808 | G36: =(G33-(G34+G35))*($O$36) -> 8441.892 | H36: =(H33-(H34+H35))*($O$36) -> 9101.9652 | I36: =(I33-(I34+I35))*($O$36) -> 8280.2184 | ... M36: =(M33-(M34+M35))*($O$36) -> 7264.0016 | O36: 0.04 | P36: Correios - Expedição de 4% do volume para 2026
A37: Saldo Peças CIF | B37: =B33-(B34+B35+B36) -> 235532.26 | C37: =C33-(C34+C35+C36) -> 169002.05 | D37: =D33-(D34+D35+D36) -> 171228.1 | E37: =E33-(E34+E35+E36) -> 173356.03 | F37: =F33-(F34+F35+F36) -> 162811.39 | G37: =G33-(G34+G35+G36) -> 202605.41 | H37: =H33-(H34+H35+H36) -> 218447.16 | I37: =I33-(I34+I35+I36) -> 198725.24 | ... M37: =M33-(M34+M35+M36) -> 174336.04 | N37: =SUM(B37:M37) -> 2382088.2 | O37: 0.06 | P37: Reajuste estimado das transportadora a partir de Abril 2026
A38: Média Custo Peça | B38: =$O$20 -> 3.3510034 | C38: =$O$20 -> 3.3510034 | D38: =$O$20 -> 3.3510034 | E38: =$O$20*(1+$O$37) -> 3.5520636 | F38: =$O$20*(1+$O$37) -> 3.5520636 | G38: =$O$20*(1+$O$37) -> 3.5520636 | H38: =$O$20*(1+$O$37) -> 3.5520636 | I38: =$O$20*(1+$O$37) -> 3.5520636 | J38: =$O$20*(1+$O$37) -> 3.5520636 | K38: =$O$20*(1+$O$37) -> 3.5520636 | L38: =$O$20*(1+$O$37) -> 3.5520636 | M38: =$O$20*(1+$O$37) -> 3.5520636
A39: Frete Peças | B39: =B37*B38 -> 789269.39 | C39: =C37*C38 -> 566326.44 | D39: =D37*D38 -> 573785.93 | E39: =E37*E38 -> 615771.65 | F39: =F37*F38 -> 578316.42 | G39: =G37*G38 -> 719667.29 | H39: =H37*H38 -> 775938.22 | I39: =I37*I38 -> 705884.7 | ... M39: =M37*M38 -> 619252.7
B42: Display
B43: Jan | C43: Fev | D43: Mar | E43: Abr | F43: Mai | G43: Jun | H43: Jul | I43: Ago | J43: Set | K43: Out | L43: Nov | M43: Dez | O43: % Indexador | P43: Premissas Orçamentárias
A44: Vol. 2026 | B44: 355513 | C44: 256084 | D44: 259468 | E44: 262386 | F44: 246586 | G44: 305569 | H44: 329025.9 | I44: 299497.8 | J44: 343180.84 | K44: 356398.76 | L44: 316897.6 | M44: 262587.2 | O44: 0.1 | P44: Aumento de 10% na expedição de produtos acabados em relação a 2025
A45: Vol FOB | B45: =B44*0.3 -> 106653.9 | C45: =C44*0.3 -> 76825.2 | D45: =D44*0.3 -> 77840.4 | E45: =E44*0.3 -> 78715.8 | F45: =F44*0.3 -> 73975.8 | G45: =G44*0.3 -> 91670.7 | H45: =H44*0.3 -> 98707.77 | I45: =I44*0.3 -> 89849.34 | ... M45: =M44*0.3 -> 78776.16
A46: Vol. Display | B46: =B35 -> 3513 | C46: =C35 -> 3215 | D46: =D35 -> 3265 | E46: =E35 -> 3091 | F46: =F35 -> 3015 | G46: =G35 -> 2851 | H46: =H35 -> 2769 | I46: =I35 -> 2643 | ... M46: =M35 -> 2211 | N46: =SUM(B46:M46) -> 33894 | O46: =SUM(B12:M12) -> 22224.92 | P46: Volume 2025
A47: Saldo Peças CIF | B47: =B44-(B45+B46) -> 245346.1 | C47: =C44-(C45+C46) -> 176043.8 | D47: =D44-(D45+D46) -> 178362.6 | E47: =E44-(E45+E46) -> 180579.2 | F47: =F44-(F45+F46) -> 169595.2 | G47: =G44-(G45+G46) -> 211047.3 | H47: =H44-(H45+H46) -> 227549.13 | I47: =I44-(I45+I46) -> 207005.46 | ... M47: =M44-(M45+M46) -> 181600.04 | O47: =SUM(B47:M47) -> 2481341.9
A48: Média Custo Display | B48: 48.11 | C48: 48.11 | D48: 48.11 | E48: =$O$14*(1+$O$37) -> 50.697693 | F48: =$O$14*(1+$O$37) -> 50.697693 | G48: =$O$14*(1+$O$37) -> 50.697693 | H48: =$O$14*(1+$O$37) -> 50.697693 | I48: =$O$14*(1+$O$37) -> 50.697693 | J48: =$O$14*(1+$O$37) -> 50.697693 | K48: =$O$14*(1+$O$37) -> 50.697693 | L48: =$O$14*(1+$O$37) -> 50.697693 | M48: =$O$14*(1+$O$37) -> 50.697693 | O48: =SUM(B46:M46) -> 33894 | P48: Previsão 2026
A49: Frete Display | B49: =B46*B48 -> 169010.43 | C49: =C46*C48 -> 154673.65 | D49: =D46*D48 -> 157079.15 | E49: =E46*E48 -> 156706.57 | F49: =F46*F48 -> 152853.54 | G49: =G46*G48 -> 144539.12 | H49: =H46*H48 -> 140381.91 | I49: =I46*I48 -> 133994 | ... M49: =M46*M48 -> 112092.6 | O49: =O48-O46 -> 11669.08 | P49: Previsão de peçs a mais para 2026 devido a epidemia de TV.
...

Sheet Embalagem 2026
E2: Ano | F2: Indexador Custo/Peça Anos
E3: 2023 | F3: 0.26
E4: 2024 | F4: 0.27
E5: 2025 | F5: =F4*I5 -> 0.281502 | H5: aplicado IGPM | I5: 1.0426
E6: 2026 | F6: =F5*I5 -> 0.29349399
A9: Cenário Orçado 2025
B10: Peças Movimentadas
B11: Jan | C11: Fev | D11: Mar | E11: Abr | F11: Mai | G11: Jun | H11: Jul | I11: Ago | J11: Set | K11: Out | L11: Nov | M11: Dez
A12: Saidas Previstas | B12: 355513 | C12: 256084 | D12: 259468 | E12: 262386 | F12: 246586 | G12: 305569 | H12: 362076 | I12: 339069 | J12: 325907 | K12: 366686 | L12: 350037 | M12: 327702
A13: Entradas Previstas | B13: 395014 | C13: 284538 | D13: 288298 | E13: 291540 | F13: 273984 | G13: 339521 | H13: 402306 | I13: 376743 | J13: 362119 | K13: 407429 | L13: 388930 | M13: 364113
A14: Movimentação Prevista | B14: =SUM(B12:B13) -> 750527 | C14: =SUM(C12:C13) -> 540622 | D14: =SUM(D12:D13) -> 547766 | E14: =SUM(E12:E13) -> 553926 | F14: =SUM(F12:F13) -> 520570 | G14: =SUM(G12:G13) -> 645090 | H14: =SUM(H12:H13) -> 764382 | I14: =SUM(I12:I13) -> 715812 | ... M14: =SUM(M12:M13) -> 691815
A15: Realizado | B15: =B14*$F$5 -> 211274.85 | C15: =C14*$F$5 -> 152186.17 | D15: =D14*$F$5 -> 154197.22 | E15: =E14*$F$5 -> 155931.28 | F15: =F14*$F$5 -> 146541.5 | G15: =G14*$F$5 -> 181594.13 | H15: =H14*$F$5 -> 215175.06 | I15: =I14*$F$5 -> 201502.51 | ... M15: =M14*$F$5 -> 194747.31
A18: Cenário Realizado 2025
B19: Peças Movimentadas
B20: Jan | C20: Fev | D20: Mar | E20: Abr | F20: Mai | G20: Jun | H20: Jul | I20: Ago | J20: Set | K20: Out | L20: Nov | M20: Dez
A21: Saidas Previstas | B21: 290266 | C21: 254556 | D21: 275881 | E21: 244955 | F21: 265129 | G21: 255126 | H21: 268456 | I21: 284799 | J21: 258534 | K21: 244917 | L21: 240875 | M21: 234787
A22: Entradas Previstas | B22: 398348 | C22: 418982 | D22: 352932 | E22: 412762 | F22: 201274 | G22: 203692 | H22: 250837 | I22: 263319 | J22: 294986 | K22: 269408.7 | L22: 264962.5 | M22: 258265.7
A23: Movimentação Prevista | B23: =SUM(B21:B22) -> 688614 | C23: =SUM(C21:C22) -> 673538 | D23: =SUM(D21:D22) -> 628813 | E23: =SUM(E21:E22) -> 657717 | F23: =SUM(F21:F22) -> 466403 | G23: =SUM(G21:G22) -> 458818 | H23: =SUM(H21:H22) -> 519293 | I23: =SUM(I21:I22) -> 548118 | ... M23: =SUM(M21:M22) -> 493052.7
A24: Realizado | B24: 66666.8 | C24: 204065.51 | D24: 220407.73 | E24: 148897.08 | F24: 102752.57 | G24: 160987.71 | H24: 173852.4 | I24: 167658.79 | J24: 89648.04 | K24: =K23*$F$31 -> 144783.71 | L24: =L23*$F$31 -> 142394.27 | M24: =M23*$F$31 -> 138795.32
E28: Valor R$emb/pç
E29: 2023 | F29: 0.26
E30: 2024 | F30: 0.27
A31: Informar memória de cálculo e conceito para a conta | E31: 2025 | F31: =F30*I31 -> 0.281502 | H31: aplicado IGPM | I31: 1.0426
E32: 2026 | F32: =F31*I31 -> 0.29349399
B34: 45658 | C34: 45689 | D34: 45717 | E34: 45748 | F34: 45778 | G34: 45809 | H34: 45839 | I34: 45870 | J34: 45901 | K34: 45931 | L34: 45962 | M34: 45992 | N34: Total
A35: TOTAL SAÍDAS | B35: 355513 | C35: 256084 | D35: 259468 | E35: 262386 | F35: 246586 | G35: 305569 | H35: 362076 | I35: 339069 | J35: 325907 | K35: 366686 | L35: 350037 | M35: 327702 | N35: =SUM(B35:M35) -> 3757083
A36: TOTAL ENTRADAS | B36: 395014 | C36: 284538 | D36: 288298 | E36: 291540 | F36: 273984 | G36: 339521 | H36: 402306 | I36: 376743 | J36: 362119 | K36: 407429 | L36: 388930 | M36: 364113 | N36: =SUM(B36:M36) -> 4174535
A37: VENDAS OBSOLETOS | B37: 120000 | C37: 120000 | D37: 120000 | E37: 120000 | F37: 120000 | G37: 120000 | H37: 120000 | I37: 120000 | J37: 120000 | K37: 120000 | L37: 120000 | M37: 120000
A40: R$ TOTAL SAÍDAS | B40: =B35*$F$31 -> 100077.62 | C40: =C35*$F$31 -> 72088.158 | D40: =D35*$F$31 -> 73040.761 | E40: =E35*$F$31 -> 73862.184 | F40: =F35*$F$31 -> 69414.452 | G40: =G35*$F$31 -> 86018.285 | H40: =H35*$F$31 -> 101925.12 | I40: =I35*$F$31 -> 95448.602 | ... M40: =M35*$F$31 -> 92248.768 | N40: =SUM(B40:M40) -> 1057626.4
A41: R$ TOTAL ENTRADAS | B41: =B36*$F$31 -> 111197.23 | C41: =C36*$F$31 -> 80098.016 | D41: =D36*$F$31 -> 81156.464 | E41: =E36*$F$31 -> 82069.093 | F41: =F36*$F$31 -> 77127.044 | G41: =G36*$F$31 -> 95575.841 | H41: =H36*$F$31 -> 113249.94 | I41: =I36*$F$31 -> 106053.91 | ... M41: =M36*$F$31 -> 102498.54 | N41: =SUM(B41:M41) -> 1175140
N42: =SUM(N40:N41) -> 2232766.3
N43: =GETPIVOTDATA("TOTAL ",[1]Geral!$B$6,"GRUPO_1","OPERAÇÃO","ÁREA","ASSIST. TÉCNICA - LOGÍSTICA","PACOTE","Materiais de Produção","CONTA CONTABIL","4100002 - MATERIAL DE EMBALAGEM","ANO",2025) -> #REF!
N44: =N42/N43-1 -> #REF!
B45: 45658 | C45: 45689 | D45: 45717 | E45: 45748 | F45: 45778 | G45: 45809 | H45: 45839 | I45: 45870 | J45: 45901 | K45: 45931 | L45: 45962 | M45: 45992 | N45: Total
B46: =B41+B40 -> 211274.85 | C46: =C41+C40 -> 152186.17 | D46: =D41+D40 -> 154197.22 | E46: =E41+E40 -> 155931.28 | F46: =F41+F40 -> 146541.5 | G46: =G41+G40 -> 181594.13 | H46: =H41+H40 -> 215175.06 | I46: =I41+I40 -> 201502.51 | ... M46: =M41+M40 -> 194747.31 | N46: =SUM(B46:M46) -> 2232766.3
A49: Cenário Proposto 2026
B50: Jan | C50: Fev | D50: Mar | E50: Abr | F50: Mai | G50: Jun | H50: Jul | I50: Ago | J50: Set | K50: Out | L50: Nov | M50: Dez | O50: Premissas Orçamentárias
A51: Saidas Previstas | B51: 246586 | C51: 256084 | D51: 259468 | E51: 262386 | F51: 355513 | G51: 305569 | H51: 329025.9 | I51: 299497.8 | J51: 343180.84 | K51: 356398.76 | L51: 316897.6 | M51: 262587.2 | O51: =SUM(B23:M23) -> 6708049.9 | P51: Peças movimentadas em 2025
A52: Entradas Previstas | B52: 197269 | C52: 435343 | D52: 337308 | E52: 341102 | F52: 462167 | G52: 244455 | H52: 296123 | I52: 269548 | J52: 308863 | K52: 392039 | L52: 348587 | M52: 288846 | O52: =SUM(B53:M53) -> 7514844.1 | P52: Previsão de peças movimentadas para 2026
A53: Movimentação Prevista | B53: =SUM(B51:B52) -> 443855 | C53: =SUM(C51:C52) -> 691427 | D53: =SUM(D51:D52) -> 596776 | E53: =SUM(E51:E52) -> 603488 | F53: 817680 | G53: =SUM(G51:G52) -> 550024 | H53: =SUM(H51:H52) -> 625148.9 | I53: =SUM(I51:I52) -> 569045.8 | J53: =SUM(J51:J52) -> 652043.84 | K53: =SUM(K51:K52) -> 748437.76 | L53: =SUM(L51:L52) -> 665484.6 | M53: =SUM(M51:M52) -> 551433.2 | O53: =(O52-O51)/O51 -> 0.12027254 | P53: % de aumento de peças movimentadas 2025 x 2026
...
